<mujoco model="arx gripper">
  <compiler angle="radian" />
  <option gravity="0 0 0"/>
  <option integrator="implicitfast" cone="elliptic" impratio="100"/>
  <visual>
    <global ellipsoidinertia="true"/>
  </visual>

<asset>
    <material name="gripper" rgba="0.8 0.8 0.8 1" />
    <material name="finger" rgba="0.1 0.1 0.1 1" />
    <mesh name="link6" file="meshes/arx_gripper/link6.STL"/>
    <mesh name="link7" file="meshes/arx_gripper/link7.STL"/>
    <mesh name="link8" file="meshes/arx_gripper/link8.STL"/>
    <mesh name="link7_collision" file="meshes/arx_gripper/link7_collision.STL"/>
    <mesh name="link8_collision" file="meshes/arx_gripper/link8_collision.STL"/>
  </asset>

  <default>
  </default>

  <worldbody>
    <body name="right_gripper" pos="0 0 0" quat="1 0 0 0">
        <site name="ft_frame" pos="0 0 0" size="0.01 0.01 0.01" rgba="1 0 0 1" type="sphere" group="1"/>
        <inertial pos="0 0 0.0" quat="0.707107 0.707107 0 0" mass="0.5" diaginertia="0.1 0.08 0.06" />
        
        <body name="eef" pos="0 0 0.0" quat="0.707 0. -0.707 0.">
            <site name="grip_site" pos="0 0 0" size="0.01 0.01 0.01" rgba="0 0 1 0.5" type="sphere" group="1"/>
            <site name="ee_x" pos="0.1 0 0" size="0.005 .1"  quat="0.707105  0 0.707108 0 " rgba="1 0 0 0" type="cylinder" group="1"/>
            <site name="ee_y" pos="0 0.1 0" size="0.005 .1" quat="0.707105 0.707108 0 0" rgba="0 1 0 0" type="cylinder" group="1"/>
            <site name="ee_z" pos="0 0 0.1" size="0.005 .1" quat="1 0 0 0" rgba="0 0 1 0" type="cylinder" group="1"/>
            <site name="grip_site_cylinder" pos="0 0 0" size="0.005 10" rgba="0 1 0 0.3" type="cylinder" group="1"/>
        </body>

        <geom pos="0.0 0.0 0.0" quat="1.0 0.0 0.0 0.0" name="link6_collision" group="0" mesh="link6" type="mesh"/>
        <geom pos="0.0 0.0 0.0" quat="1.0 0.0 0.0 0.0" name="link6_visual" material="gripper" group="1" contype="0" conaffinity="0" mesh="link6" type="mesh"/>

        <body name="rightfinger" pos="0.08657 0.024896 -0.0002436" quat="1.0 0 0 0">
          <joint name="finger_joint1" pos="0 0 0" axis="0 1 0" type="slide" limited="true" range="0.002 0.044" damping="0.1" armature="0.01" frictionloss="0.1"/>
          
          <geom pos="0.0 0.0 0.0" quat="1.0 0.0 0.0 0.0" name="right_finger_visual" material="finger" group="1" contype="0" conaffinity="0" mesh="link7" type="mesh"/>
          
          <geom name="right_finger_collision" type="box" size="0.04 0.005 0.015" pos="0.045 -0.02 0" group="0" 
                friction="2.0 0.005 0.0001" solimp="0.95 0.99 0.001" solref="0.01 1"/>
        </body>

        <body name="leftfinger" pos="0.08657 -0.0249 -0.00024366" quat="1.0 0 0 0">
          <joint name="finger_joint2" pos="0 0 0" axis="0 -1 0" type="slide" limited="true" range="0.002 0.044" damping="0.1" armature="0.01" frictionloss="0.1"/>
          
          <geom pos="0.0 0.0 0.0" quat="1.0 0.0 0.0 0.0" name="left_finger_visual" material="finger" group="1" contype="0" conaffinity="0" mesh="link8" type="mesh"/>
          
          <geom name="left_finger_collision" type="box" size="0.04 0.005 0.015" pos="0.045 0.02 0" group="0" 
                friction="2.0 0.005 0.0001" solimp="0.95 0.99 0.001" solref="0.01 1"/>
        </body>
    </body>
  </worldbody>

  <actuator>
    <position ctrllimited="true" ctrlrange="0.000 0.044" joint="finger_joint1" kp="1000" name="gripper_finger_joint1" forcelimited="true" forcerange="-50 50"/>
    <position ctrllimited="true" ctrlrange="0.000 0.044" joint="finger_joint2" kp="1000" name="gripper_finger_joint2" forcelimited="true" forcerange="-50 50"/>
  </actuator>
  <sensor>
      <force name="force_ee" site="ft_frame"/>
      <torque name="torque_ee" site="ft_frame"/>
  </sensor>
</mujoco>